Workbook

Sheet Loads
A1: General Chiploads
A2: Material | B2: 0.125 | C2: 0.25 | D2: 0.375 | E2: 0.5 | G2: Tool | H2: Chipload | I2: Reduction | J2: Total
A3: Hardwood | B3: 0.003 | C3: 0.009 | D3: 0.015 | E3: 0.019 | G3: Compression | H3: 0.0145 | I3: 0.15 | J3: =SUM(H3*(1-I3)) -> 0.012325
A4: Plywood | B4: 0.004 | C4: 0.012 | D4: 0.018 | E4: 0.022 | G4: DC | I4: 0.15 | J4: =SUM(J3*(1-I4)) -> 0.01047625
A5: MDF | B5: 0.004 | C5: 0.0145 | D5: 0.02 | E5: 0.025
A6: Foam | B6: 0.008 | C6: 0.012 | D6: 0.025 | E6: 0.025
A7: Acrylic | B7: 0.002 | C7: 0.0075 | D7: 0.01 | E7: 0.01
A8: HDPE | B8: 0.003 | C8: 0.008 | D8: 0.008 | E8: 0.014
A15: Adaptive - Optimal Loads | G15: Long Flute Reduction Table
A16: Material | B16: 0.125 | C16: 0.25 | D16: 0.375 | E16: 0.5 | G16: Flute Length/Diameter Ratio | J16: Chipload Reduction
A17: Hardwood | B17: 0.0075 | C17: 0.015 | D17: 0.0225 | E17: 0.03 | G17: 2 to 1 | J17: 0
A18: Plywood | B18: 0.01 | C18: 0.02 | D18: 0.03 | E18: 0.04 | G18: 3 to 1 | J18: 0.15
A19: MDF | B19: 0.01 | C19: 0.02 | D19: 0.03 | E19: 0.04 | G19: 4 to 1 | J19: 0.2
A20: Foam | B20: 0.015 | C20: 0.03 | D20: 0.045 | E20: 0.06 | G20: 5 to 1 and above | J20: 0.25
A24: Notes
A25: In Fusion just put the default values and adjust per toolpath. For finishing cuts reduce feedrate by about 30%. For a Bore, use the Bore sheet: type its spindle and feed, and leave Feed per Tooth alone.

Sheet Bore
A1: Bore toolpaths | Z1: =IF($B$3="","",IFERROR(INDEX(Loads!$B$3:$E$8,MATCH($B$3,Loads!$A$3:$A$8,0),1),"")) -> 0.004
A2: Setting | B2: Value | Z2: =IF($B$3="","",IFERROR(INDEX(Loads!$B$3:$E$8,MATCH($B$3,Loads!$A$3:$A$8,0),2),"")) -> 0.0145
A3: Material | B3: MDF | Z3: =IF($B$3="","",IFERROR(INDEX(Loads!$B$3:$E$8,MATCH($B$3,Loads!$A$3:$A$8,0),3),"")) -> 0.02
A4: Tool diameter (in) | B4: 0.25 | Z4: =IF($B$3="","",IFERROR(INDEX(Loads!$B$3:$E$8,MATCH($B$3,Loads!$A$3:$A$8,0),4),"")) -> 0.025
A5: Hole diameter (in) | B5: 0.315 | Z5: =IF(OR($B$4="",$B$5="",$B$5<=$B$4),"",($B$5-$B$4)/2) -> 0.0325
A6: Flutes | B6: 2 | Z6: =IF(OR($B$4="",$B$5=""),"",IF($B$5<=$B$4,Z9,Z8)) -> 39.496835
A7: Ramp angle (deg) | B7: 30 | Z7: =IF(OR(B29="",$B$25="",$B$6<1,$B$26=""),"",B29*$B$26/($B$25*$B$6)) -> 5065.2149
A8: Thickness (in) | B8: 0.75 | Z8: =IF(OR(Z5="",$B$25="",$B$7<5,$B$7>45,$B$38<=0),"",MIN(MIN($B$39,60*SQRT($B$38*Z5))/COS(RADIANS($B$7)),$B$40/SIN(RADIANS($B$7)))) -> 39.496835
A9: Chipload override | Z9: =IF(OR($B$25="",$B$6<1),"",MIN($B$42,$B$25*$B$6*$B$41)) -> 400
A11: Type into Fusion
A12: Setting | B12: Value
A13: Result | B13: =IF(OR($B$4="",$B$5=""),"",IF($B$5<=$B$4,"Tool is larger than the hole. Numbers below are a straight cut.",IF(OR($B$7<5,$B$7>45),"Use a ramp from 5 to 45 degrees.",IF($B$6<1,"Enter the flute count.",IF($B$22="","Pick a material on the Loads sheet.","Ready"))))) -> Ready
A14: Spindle (rpm) | B14: =IF(Z7="","",MIN($B$41,MAX(1000,ROUND(Z7/1000,0)*1000))) -> 5000
A15: Feed for cutting, leads, ramp, and plunge | B15: =IF(OR(Z6="",Z6<=0),"",IF(Z6<5,ROUND(Z6,1),FLOOR(Z6/5,1)*5)) -> 35
A16: Chipload | B16: =IF($B$25="","",$B$25) -> 0.0145
A17: Ramp angle (deg) | B17: =$B$7 -> 30
A18: Bottom of the hole | B18: 0.02 in past the sheet
A20: How these numbers were made
A21: Setting | B21: Value
A22: General chipload | B22: =IF(OR($B$4="",$B$4<=0,Z1=""),"",IF($B$4<=Loads!$B$2,Z1,IF($B$4>=Loads!$E$2,Z4,IF($B$4<=Loads!$C$2,Z1+(Z2-Z1)*($B$4-Loads!$B$2)/(Loads!$C$2-Loads!$B$2),IF($B$4<=Loads!$D$2,Z2+(Z3-Z2)*($B$4-Loads!$C$2)/(Loads!$D$2-Loads!$C$2),Z3+(Z4-Z3)*($B$4-Loads!$D$2)/(Loads!$E$2-Loads!$D$2)))))) -> 0.0145
A23: Tool / hole | B23: =IF(OR($B$4="",$B$5="",$B$5<=0),"",$B$4/$B$5) -> 0.79365079
A24: Bore factor | B24: =IF($B$23="","",IF($B$23>=1,1,IF($B$23>=$D$3,$E$3,IF($B$23>=$D$4,$E$4,$E$5)))) -> 0
A25: Wall chipload | B25: =IF($B$9<>"",$B$9,IF($B$22="","",$B$22)) -> 0.0145
A26: Arc ratio | B26: =IF(OR($B$4="",$B$5="",$B$5<=0),"",IF($B$5<=$B$4,1,$B$5/($B$5-$B$4))) -> 4.8461538
A27: Centerline radius (in) | B27: =IF(Z5="","n/a",Z5) -> 0.0325
A28: Center chipload | B28: =IF(OR($B$25="",$B$26=""),"",$B$25/$B$26) -> 0.0029920635
A29: Sideways speed (in/min) | B29: =IF($B$15="","",IF($B$5<=$B$4,$B$15,$B$15*COS(RADIANS($B$7)))) -> 30.310889
A30: Vertical speed (in/min) | B30: =IF($B$15="","",IF($B$5<=$B$4,0,$B$15*SIN(RADIANS($B$7)))) -> 17.5
A31: Actual wall chip | B31: =IF(OR($B$14="",$B$29="",$B$26=""),"",$B$29*$B$26/($B$14*$B$6)) -> 0.014689123
A32: Surface speed (ft/min) | B32: =IF(OR($B$14="",$B$4=""),"",PI()*$B$4*$B$14/12) -> 327.24923
A33: Pitch (in/rev) | B33: =IF(Z5="","n/a",PI()*($B$5-$B$4)*TAN(RADIANS($B$7))) -> 0.11789696
A34: Turns through the thickness | B34: =IF(OR(B33="n/a",B33="",$B$8=""),"n/a",$B$8/B33) -> 6.3614873
A36: Machine limits
A37: Setting | B37: Value
A38: Smooth acceleration (in/sec2) | B38: 10
A39: Sideways cap (in/min) | B39: 50
A40: Vertical cap (in/min) | B40: 20
A41: Max spindle (rpm) | B41: 18000
A42: Straight-cut cap (in/min) | B42: 400
A44: Rules
...
